<?xml version="1.0"?>
<robot name="physics">

  <material name="gray">
    <color rgba="0.8 0.8 0.8 1"/>
  </material>
 
  <material name="white">
    <color rgba="1 1 1 1"/>
  </material>

  <link name="base_link">
    <visual>
      <geometry>
        <box size="0.065 0.0815 0.038"/>
      </geometry>
      <origin rpy="0 0 0" xyz="0 0 0.02"/>
      <material name="gray"/>
    </visual>
    <inertial>
      <mass value="1"/>
      <inertia ixx="0.0004" ixy="0.0" ixz="0.0" iyy="0.001" iyz="0.0" izz="0.0006"/>
      <origin rpy="0 0 0" xyz="0 0 0"/>
    </inertial>
  </link>
  
  <link name="base_servo">
    <visual>
      <geometry>
        <box size="0.04 0.06 0.038"/>
      </geometry>
      <origin rpy="0 0 0" xyz="0 0 0.055"/>
      <material name="white"/>
    </visual>
    <inertial>
      <mass value="1"/>
      <inertia ixx="0.0004" ixy="0.0" ixz="0.0" iyy="0.001" iyz="0.0" izz="0.0006"/>
      <origin rpy="0 0 0" xyz="0 0 0"/>
    </inertial>
  </link>

  <link name="shoulder_servo">
    <visual>
      <geometry>
        <box size="0.0725 0.045 0.083"/>
      </geometry>
      <origin rpy="0 0 0" xyz="0.0 0.01 0.116"/>
      <material name="white"/>
    </visual>

    <inertial>
      <mass value="1"/>
      <inertia ixx="0.0004" ixy="0.0" ixz="0.0" iyy="0.001" iyz="0.0" izz="0.0006"/>
      <origin rpy="0 0 0" xyz="0 0 0"/>
    </inertial>
    
  </link>

  <link name="elbow_servo">
    <visual>
      <geometry>
        <box size="0.035 0.045 0.02"/>
      </geometry>
      <origin rpy="0 0 0" xyz="0 -0.015 0.027"/>
      <material name="white"/>
    </visual>
    <inertial>
      <mass value="1"/>
      <inertia ixx="0.0004" ixy="0.0" ixz="0.0" iyy="0.001" iyz="0.0" izz="0.0006"/>
      <origin rpy="0 0 0" xyz="0 0 0"/>
    </inertial>
      
  </link>

  <link name="forearm_link">
    <visual>
      <geometry>
        <box size="0.03 0.035 0.14"/>
      </geometry>
      <origin rpy="0 0 0" xyz="0 0 0.052"/>
      <material name="white"/>
    </visual>
    <inertial>
      <mass value="1"/>
      <inertia ixx="0.0004" ixy="0.0" ixz="0.0" iyy="0.001" iyz="0.0" izz="0.0006"/>
      <origin rpy="0 0 0" xyz="0 0 0"/>
    </inertial>
    
  </link>

  <link name="wrist_servo">
    <visual>
      <geometry>
        <box size="0.025 0.04 0.035"/>
      </geometry>
      <origin rpy="0 0 0" xyz="0 0 0.008"/>
      <material name="white"/>
    </visual>
    <inertial>
      <mass value="1"/>
      <inertia ixx="0.0004" ixy="0.0" ixz="0.0" iyy="0.001" iyz="0.0" izz="0.0006"/>
      <origin rpy="0 0 0" xyz="0 0 0"/>
    </inertial>
      
  </link>
 
  
  <link name="l5_1_A_link">
    <visual>
      <geometry>
        <mesh filename="meshes/L5_1_A.stl"/>
      </geometry>
      <origin xyz="-0.003489 -0.311007 -0.3" rpy="0 0 0"/>
      <material name="white"/>
    </visual>
    <inertial>
      <mass value="1"/>
      <inertia ixx="0.0004" ixy="0.0" ixz="0.0" iyy="0.001" iyz="0.0" izz="0.0006"/>
      <origin rpy="0 0 0" xyz="0 0 0"/>
    </inertial>
      
  </link>
  
  <link name="l5_1_B_link">
    <visual>
      <geometry>
        <mesh filename="meshes/L5_1_B.stl"/>
      </geometry>
      <origin xyz="-0.024489 -0.311007 -0.3" rpy="0 0 0"/>
      <material name="white"/>
    </visual>
    <inertial>
      <mass value="1"/>
      <inertia ixx="0.0004" ixy="0.0" ixz="0.0" iyy="0.001" iyz="0.0" izz="0.0006"/>
      <origin rpy="0 0 0" xyz="0 0 0"/>
    </inertial>
      
  </link>
  

  <link name="l5_3_A_link">
    <visual>
      <geometry>
        <mesh filename="meshes/L5_3_A.stl"/>
      </geometry>
      <origin xyz="0.039711 -0.304219 -0.3" rpy="0 0 0"/>
      <material name="white"/>
    </visual>
    <inertial>
      <mass value="1"/>
      <inertia ixx="0.0004" ixy="0.0" ixz="0.0" iyy="0.001" iyz="0.0" izz="0.0006"/>
      <origin rpy="0 0 0" xyz="0 0 0"/>
    </inertial>
      
  </link>

  <link name="l5_3_B_link">
    <visual>
      <geometry>
        <mesh filename="meshes/L5_3_B.stl"/>
      </geometry>
      <origin xyz="-0.067689 -0.304219 -0.3" rpy="0 0 0"/>
      <material name="white"/>
    </visual>
    <inertial>
      <mass value="1"/>
      <inertia ixx="0.0004" ixy="0.0" ixz="0.0" iyy="0.001" iyz="0.0" izz="0.0006"/>
      <origin rpy="0 0 0" xyz="0 0 0"/>
    </inertial>
      
  </link>


  

  
  
  <joint name="base_joint" type="revolute">
    <axis xyz="0 0 1"/>
    <limit effort="1000.0" lower="-3.14" upper="3.14" velocity="0.5"/>
    <parent link="base_servo"/>
    <child link="shoulder_servo"/>
    <origin xyz="0 0 0"/>
  </joint>


  <joint name="shoulder_joint" type="revolute">
    <axis xyz="1 0 0"/>
    <limit effort="1000.0" lower="-1.57" upper="1.57" velocity="0.5"/>
    <parent link="shoulder_servo"/>
    <child link="elbow_servo"/>
    <origin xyz="0 0.009 0.12"/>
  </joint>

  <joint name="elbow_joint" type="revolute">
    <axis xyz="1 0 0"/>
    <limit effort="1000.0" lower="-0.6" upper="2.8" velocity="0.5"/>
    <parent link="elbow_servo"/>
    <child link="forearm_link"/>
    <origin xyz="0 -0.032 0.05"/>
  </joint>

  <joint name="wrist_joint" type="revolute">
    <axis xyz="0 1 0"/>
    <limit effort="1000.0" lower="-1.57" upper="1.57" velocity="0.5"/>
    <parent link="forearm_link"/>
    <child link="wrist_servo"/>
    <origin xyz="0 0 0.11"/>
  </joint>
  
  <joint name="gripper_joint" type="revolute">
    <axis xyz="0 0 1"/>
    <limit effort="1000.0" lower="-1.57" upper="0" velocity="0.5"/>
    <parent link="wrist_servo"/>
    <child link="l5_1_A_link"/>
    <!-- Change z for height of gripper -->
    <origin xyz="-0.009511 0.0501 0.053148" rpy="1.57 0 0"/>
  </joint>

  <joint name="L4_to_L5_1_B" type="revolute">
    <axis xyz="0 0 1"/>
    <limit effort="1000.0" lower="-1.57" upper="1.57" velocity="0.5"/>
    <parent link="wrist_servo"/>
    <child link="l5_1_B_link"/>
    <!-- Change z for height of gripper -->
    <origin xyz="0.011489 0.0501 0.053148" rpy="1.57 0 0"/>
    <mimic joint="gripper_joint" multiplier="-1" offset="0"/>
  </joint>


  <joint name="L5_1_A_to_L5_3_A" type="revolute">
    <axis xyz="0 0 1"/>
    <limit effort="1000.0" lower="-1.57" upper="1.57" velocity="0.5"/>
    <parent link="l5_1_A_link"/>
    <child link="l5_3_A_link"/>
    <origin xyz="-0.0432 0 -0.008" rpy="0 0 0"/>
    <mimic joint="gripper_joint" multiplier="-1" offset="0"/>
  </joint>
  
  <joint name="L5_1_B_to_L5_3_B" type="revolute">
    <axis xyz="0 0 1"/>
    <limit effort="1000.0" lower="-1.57" upper="0" velocity="0.5"/>
    <parent link="l5_1_B_link"/>
    <child link="l5_3_B_link"/>
    <origin xyz="0.0432 0 -0.008" rpy="0 0 0"/>
    <mimic joint="L4_to_L5_1_B" multiplier="-1" offset="0"/>
  </joint>
  
</robot>